<?xml version="1.0" encoding="UTF-8"?>
<!-- Generated by org.testng.reporters.JUnitXMLReporter -->
<testsuite hostname="vimal" ignored="0" name="Login Test" tests="3" failures="1" timestamp="2022-12-13T00:49:12 GMT" time="25.417" errors="0">
  <testcase name="UserShouldLoginSuccessfullyWithValidCredentials" time="0.577" classname="com.herokuapp.internet.testsuit.LoginTest"/>
  <testcase name="verifyThePasswordErrorMessage" time="0.518" classname="com.herokuapp.internet.testsuit.LoginTest"/>
  <testcase name="verifyTheUsernameErrorMessage" time="0.485" classname="com.herokuapp.internet.testsuit.LoginTest">
    <failure type="java.lang.AssertionError" message="expected [2] but found [1]">
      <![CDATA[java.lang.AssertionError: expected [2] but found [1]
at com.herokuapp.internet.testsuit.LoginTest.verifyTheUsernameErrorMessage(LoginTest.java:35)
at java.util.ArrayList.forEach(ArrayList.java:1249)
at com.intellij.rt.testng.IDEARemoteTestNG.run(IDEARemoteTestNG.java:66)
at com.intellij.rt.testng.RemoteTestNGStarter.main(RemoteTestNGStarter.java:109)
... Removed 30 stack frames]]>
    </failure>
  </testcase> <!-- verifyTheUsernameErrorMessage -->
</testsuite> <!-- Login Test -->
